Workbook
Name Slicer_Attribute: #N/A
Name Slicer_ID: #N/A
Name Slicer_Impact_Analysis_Bucket: #N/A
Name Slicer_Target_Domain: #N/A
Name tbl_DDX_Renovate_Backlog: 'DDX Renovate Backlog'!$B$4:$S$179

Sheet READ ME
B2: DOCUMENT OVERVIEW
B3: Purpose | C3: This document outlines the business requirements for the data that will exist in the Gold Layer. It identifies the critical data fields required for Activation and Analytics/Reporting use cases and organizes them by domain + sub-domain, to guide the tech teams in building our final table structures.
B5: Context | C5: The fields listed here are a curated subset of the entire L'Oréal data ecosystem, compiled from three main sources: 1) Global Granular Data Model (GDM): The mandated analytcis data model from L'Oréal Global 2) One Consumer Profile: The mandated activation data model from L'Oréal Global 3) LUSA B2C Business Glossary: Our glossary of critical data fields that have been identified and validated by LUSA stakeholders across business & IT teams to date (also accounting for the subset of these fields that exist in the C360 data model tables in DDX)
B6: ** ALL Domains, BAR Activation KPIs, and KPI Catalog sheets are the three sources of truth when it comes to what needs to be in the golden layer**
B7: DOCUMENT NAVIGATION (SHEET GUIDE)
B8: All Domains | C8: This sheet provides a comprehensive list of all critical data fields, organized by Domain and Subdomain. The purpose of this categorization is to propose a logical structure for the tables in the Gold Layer. This view should be used to understand what data is required and how it's grouped together.
B9: BAR Activation KPIs | C9: A focused and highly prioritized subset of calculated metrics that were historically used to populate the BAR dashboards and are now critical for immediate digital activation. These are derived from the foundational attributes defined in the All Domains view, with all of them being prioritized for the Golden Layer build.
B10: KPI Catalog | C10: The holistic, comprehensive master list of LUSA's business-critical metrics for all measurement needs. It encompasses the entire set of KPIs, including the subset listed under BAR Activation KPIs. The purpose of this sheet is to serve as the definitive source of truth for metrics leveraged in long-term reporting, advanced analytics (e.g., the DDX Tech dashboard), and overall strategic business intelligence.
B11: Gap Analysis | C11: This sheet provides a comparative view of our required fields against the two source assets (GDM and the Business Glossary). It highlights overlaps, identifies net-new fields required by the US market, and shows domain fill rates. This context is crucial for understanding the source and completeness of our data requirements.
B13: KEY CONCEPTS FOR TABLE DESIGN
B14: Customer Relationship (1-to-1 vs. 1-to-Many) | C14: This is the most critical concept. It defines how data relates back to a single, unique customer. 1.) 1-to-1: The data point is an attribute of the customer and can be represented once per person (e.g., a customer's single date of birth). These fields belong in the core customer table. 2.) 1-to-Many: The data point represents an event or item associated with the customer, where one customer can have many records (e.g., a customer's many transactions over time). These fields belong in separate, related tables.
B21: Domain Object Relationship (1-to-1 vs. 1-to-many) | C21: This defines how data relates to the primary object of its domain (e.g., a single Campaign ID or a single Order ID). 1.) 1-to-1: The data represents a single record for that object (e.g., the Order Header contains one row of summary data for one order). 2.) 1-to-Many: The data can have many records for that single object (e.g., the Order Line table can contain many product lines for one order).
B29: ALL DOMAINS SHEET STRUCTURE & LOGIC GUIDE
B30: Customer Domain | C30: The Customer domain is the central entity. Its core principle is that each row represents a single, unique customer (1-to-1 relationship). All subdomains here are attributes that can be directly assigned to an individual. - Identity: Basic 1st-party identifiers and descriptive information. - Contactability: High-level KPIs that summarize a customer's contact status. - Acquisition Data: Information detailing how and when a customer was first acquired. - BMDM (Beauty Data): The customer's "Beauty Profile" (e.g., hair color, eye color). - Loyalty: Aggregated KPIs related to the customer's loyalty status (e.g., current tier). - Interaction KPIs: Aggregated metrics summarizing customer engagement. - Transactional KPIs: Aggregated metrics summarizing purchasing behavior (e.g., LTV). - 3P Demographic Data: Appended demographic data from TransUnion.
B42: Contacts Domain | C42: This domain contains all specific contact points on file for a customer, such as every email address or phone number. - Key Design Consideration: We have intentionally separated this from the Customer domain for data processing efficiency. It is designed with a 1-to-many relationship to the customer, meaning a single customer can have multiple rows (one for each contact point). This structure is more scalable and easier to query for activation than trying to fit multiple contacts into a single customer row.
B50: Transactions Domain | C50: This domain holds event-level purchase data. The primary object is the Order. - Order Header: Provides information aggregated to a single order, such as net sales, promotional value, and order date. (Customer Relationship: 1-to-many; Domain Object Relationship: 1-to-1 with Order). - Order Line: Contains granular information for each item within an order, such as line number, line type, and product-level promotional value. (Customer Relationship: 1-to-many; Domain Object Relationship: 1-to-many with Order).L
B58: Campaign Domain | C58: This domain contains all information related to our marketing campaigns. The primary object is the Campaign. - Campaign Master: The aggregate view of a campaign, including total net sales, message channel, and start/end dates. This data is not at the customer level. (Customer Relationship: N/A; Domain Object Relationship: 1-to-1 with Campaign). - Campaign Interactions: Event-level data tracking individual customer interactions with a campaign, such as an email open, a click, or a promo application. (Customer Relationship: 1-to-many; Domain Object Relationship: 1-to-many with Campaign). - Loyalty Campaign Interactions: Similar to the above, but focused on interactions within loyalty-specific campaigns, such as a customer upgrading their tier as a result of the campaign. (Customer Relationship: 1-to-many; Domain Object Relationship: 1-to-many with Campaign).
B69: Interactions Domain | C69: This domain is a log of all granular, event-level customer engagements. The primary object is the individual Interaction Event. - Interaction Tracking: A comprehensive log of all customer interactions, both online and offline (e.g., subscription changes, loyalty events, orders). Every row is a single interaction. (Customer Relationship: 1-to-many; Domain Object Relationship: 1-to-1 with Interaction). - Website Interactions: A specific log for all customer interactions happening online, with data sourced directly from Google Analytics 4 (GA4), which has a unique data structure. (Customer Relationship: 1-to-many; Domain Object Relationship: 1-to-1 with Interaction).
B79: Link to GA4 glossary
B80: Link to OneConsumerModel

Sheet TAXONOMY GUIDE
D2: Purpose of This Reference
D3: This document explains how Gold Layer data is organized in the "All Domains" sheet so the CDP team can build an accurate, business-friendly taxonomy in HighTouch without misinterpreting table structure or data grain. The most important concept to keep in mind is that not all attributes behave like customer-level traits. Understanding the relationship between Domain, Sub-Domain, and Object grain is critical to avoiding duplicate counts, incorrect joins, and confusing marketer experiences. If field nuances are still unclear with this added context, check definitions for greater clarity.
D5: Key Terms | E5: Definition | G5: How to use it (CDP quick guidance)
D6: Domain | E6: The high-level category (Customer, Transactions, etc…) individual data fields belong to, strongly related to the "Object in Focus" for any given field. | G6: Start here to understand what type of data / object you’re working with.
D7: Sub-Domain | E7: The high level data sub-category individual data fields belong to, providing guidance for table-level grouping (typically maps to a unique Gold table or tight table set). | G7: Use as the primary “table context” for taxonomy placement.
D8: Object in focus | E8: The primary (but often not only) entity a given domain + sub-domain/table describes (e.g., Customer, Customer Order, Campaign, Interaction, Product). | G8: Identify the specific object the sub-domain tables + fields are related to. Helps distinguish similar-looking fields that mean different things in different tables.
D9: Customer Relationship | E9: Relationship to customer: 1:1 = one row per customer; 1:many = multiple rows per customer. | G9: Always check this first. If 1:many, treat as record/event-level unless explicitly rolled up. Helps distinguish similar-looking fields + contextualize field utility for any given use case.
D10: Domain Object Relationship | E10: Relationship to the domain’s object (e.g., Order Header = 1 row per order vs Order Line = many rows per order). | G10: Use to tell “master/aggregate tables” vs “detail/event tables.” Helps distinguish similar-looking fields + contextualize field utility for any given use case.
D12: [Customer] Domain Object in focus: Unique Customer (customer-level traits, rollups, and customer-level enrichments). Goal: Sub-domains here all contain data that can be represented on a single row per customer, making them our primary source of truth for audience segmentation
D13: Sub-Domain Overview (1:1 Unique Customer Relationship)
D14: Domain (Object) | E14: Sub-Domain | F14: What this table/sub-domain represents (business view) | G14: Customer Relationship | H14: Domain Object (Customer) Relationship | I14: Gold Table mapping (from All Domains)
D15: Customer | E15: Identity | F15: Core customer identifiers + foundational profile attributes used across the ecosystem (IDs, brand/division, basic profile fields). | G15: one-to-one | H15: one-to-one | I15: prod_us_catalog.ddx_b2c_gold.cdp__identity_v
D16: Customer | E16: Campaign Control Group | F16: Customer-level flags/dates indicating control-group assignment status for campaign measurement. | G16: one-to-one | H16: one-to-one | I16: TBD
D17: Customer | E17: Contactability | F17: Customer-level “rollups” that summarize contactability/permission status (intended to be customer-safe traits). | G17: one-to-one | H17: one-to-one | I17: prod_us_catalog.ddx_b2c_gold.cdp__contactability_v
D18: Customer | E18: Loyalty | F18: Customer-level loyalty membership attributes and loyalty KPIs/balances at the customer grain. | G18: one-to-one | H18: one-to-one | I18: prod_us_catalog.ddx_b2c_gold.cdp__loyalty_v
D19: Customer | E19: Transactional KPIs | F19: Customer-level purchase rollups (e.g., frequency/recency/aggregates) computed from transactional data. | G19: one-to-one | H19: one-to-one | I19: prod_us_catalog.ddx_b2c_gold.cdp__transactional_kpis_v
D20: Customer | E20: Interaction KPIs | F20: Customer-level interaction rollups (derived metrics summarizing customer interaction behavior). | G20: one-to-one | H20: one-to-one | I20: prod_us_catalog.ddx_b2c_gold.cdp__acquisition_interaction_data_v
D21: Customer | E21: Acquisition Data | F21: Customer-level acquisition descriptors (current-state view; undergoing reconciliation into cleaner outputs). | G21: one-to-one | H21: one-to-one | I21: prod_us_catalog.ddx_b2c_gold.cdp__acquisition_interaction_data_v
D22: Customer | E22: BMDM (Beauty Data) | F22: Customer-level “beauty profile” attributes (enriched beauty-related descriptors at customer grain). | G22: one-to-one | H22: one-to-one | I22: prod_us_catalog.ddx_b2c_gold.cdp__beauty_profile_v
D23: Customer | E23: 3P Demographic Data | F23: Customer-level appended/enriched 3P demographic signals (e.g., TransUnion attributes) including appended location fields. | G23: one-to-one | H23: one-to-one | I23: prod_us_catalog.ddx_b2c_gold.3p_demographic_v
D25: [Customer - Contacts] Domain Object in focus: Unique contact value (email, phone, and other contact records) tied back to the customer. What this means in practice: These tables are inherently customer 1:many and are record-level. They house the customer PII data critical to executing marketing campaigns across platforms in just 3 fields (contact_type, _sub_type, and _value), allowing for multiple rows per unique customer. This format offers greater efficiency and agility vs. representing all contact values in the main 1:1 customer table - allowing users to strategically match only relevant contact info to customer segments in HighTouch vs. parsing/querying through dozens of redundant fields. Still, they require careful treatment if aggregated /transformed/processed to ensure that the opt-in statuses attached to individual customer contact values stay accurate (Ex.- customers often have multiple emails/phone numbers, each with their own unique opt-in status).
D26: Sub-Domain Overview (1:M Unique Customer Relationship | 1:1 Contact Value Relationship)
D27: Domain (Object) | E27: Sub-Domain | F27: What this table/sub-domain represents (business view) | G27: Customer Relationship | H27: Domain Object (Contact Value) Relationship | I27: Gold Table mapping (from All Domains)
D28: Customer – Contacts | E28: Contact Info | F28: Contact-value-level records (e.g., each email / phone / contact value). Used for granular consent and contact-value attributes. | G28: one-to-many | H28: one-to-one | I28: prod_us_catalog.ddx_b2c_gold.cdp__contact_info_v
D30: [Customer] - AA Models Domain Object in focus: Unique Advanced Analytics Model Output (customer classifications/scores), tied back to the customer. What this means in practice: Typically customer 1:M because one customer can have multiple model outputs (different models, scores, or segments). This is not customer-level and not event-level; it’s “model output record” level. This format allows advanced analytics based segmentation to be multi-dimensional.
D31: Sub-Domain Overview (1:M Unique Customer Relationship | 1:1 Customer Model Output Relationship)
D32: Domain (Object) | E32: Sub-Domain | F32: What this table/sub-domain represents (business view) | G32: Customer Relationship | H32: Domain Object (Model Output) Relationship | I32: Gold Table mapping (from All Domains)
D33: Customer - AA Models | E33: Predictive attributes | F33: Model-driven customer attributes (scores/segments/classes). Often one row per customer per model output type/version. | G33: one-to-many | H33: one-to-one | I33: prod_us_catalog.ddx_b2c_gold.cdp__bar_customer_models_v
D35: [Interactions] Domain Object in focus: Unique Customer Interaction (events/activities) connected to known customers Goal: Almost universally customer 1:M because one customer typically records multiple interactions with a given brand (sign-ups, clicks, purchases, etc..). This is customer event-level data at the smallest grain possible, allowing for nuanced customer segmentation to aide complex analysis and activation efforts.
D36: Sub-Domain Overview (1:M Unique Customer Relationship | 1:1 Interaction Relationship)
D37: Domain (Object) | E37: Sub-Domain | F37: What this table/sub-domain represents (business view) | G37: Customer Relationship | H37: Domain Object (Interaction) Relationship | I37: Gold Table mapping (from All Domains)
D38: Interactions | E38: Interaction Tracking | F38: Master table of known-customer interaction records across sources (customer-linked interactions), including roll-ups from loyalty, campaign, and GA4 tables. | G38: one-to-many | H38: one-to-one | I38: prod_us_catalog.ddx_b2c_gold.cdp__acquisition_interaction_level_data_v
D39: Interactions | E39: Loyalty Interactions | F39: Loyalty interaction/event records kept separate for cleaner loyalty analytics and modeling. | G39: one-to-many | H39: one-to-one | I39: prod_us_catalog.ddx_b2c_gold.cdp__loyalty_event_v
D41: [Website Browsing (GA4)] Domain Object in focus: Unique GA4 User ID connected to known & unknown (anonymous) customers Goal: A comination of customer 1:M and 1:1 because one known customer will commonly have multiple GA4 IDs associated with them given the constraints associated with GA4 identity resolution. Any IDs we can reconcile to known customer IDs enable customer profile enrichment. When GA4 User IDs can be matched to known customers, we pull their interaction data into our master Interaction Tracking table.
D42: Sub-Domain Overview (1:M Unique Customer Relationship | Mixed GA4 User Relationship)
D43: Domain (Object) | E43: Sub-Domain | F43: What this table/sub-domain represents (business view) | G43: Customer Relationship | H43: Domain Object (GA4 User) Relationship | I43: Gold Table mapping (from All Domains)
D44: GA4 User | E44: Website Interactions - User view | F44: GA4 user-level view (GA4 users with associated fields; may include known/anonymous handling depending on GA4 joinability). | G44: one-to-many | H44: one-to-one | I44: prod_us_catalog..ddx_b2c_gold.fact_ga4_users
D45: GA4 User | E45: Website interactions - Daily event table | F45: GA4 daily event-level table (interaction events aggregated/represented at daily event grain). | G45: one-to-many | H45: one-to-many | I45: prod_us_catalog..ddx_b2c_gold.fact_ga4_daily_events
D47: [Transactions] Domain Object in focus: Unique Order / Transaction (any purchase) connected to known & unknown (anonymous) customers Goal: Customer → transactions is customer 1:many. Within the domain, header vs line are different object grains, both relating to customer transactions over time. Line-level data is our primary source of truth to calculate order-level KPIs (Header table) and identify product-level customer purchase patterns. Meanwhile, order-level data is our primary source of truth to calculate customer-level transactional KPIs.
D48: Sub-Domain Overview (1:M Unique Customer Relationship | Mixed Order Relationship)
...

Sheet Renovate Timeline
I1: We are here
F3: M1 - Jan | H3: M2-Feb | L3: M3-Mar | Q3: M4-April | U3: M5-May | Y3: M6-June | AD3: M7-July | AH3: M8-AUG | AM3: M9-SEP | AQ3: M10-Oct | AU3: M11- Nov
F4: Wk1 | G4: Wk2 | H4: Wk3 | I4: Wk4 | J4: Wk5 | K4: Wk6 | L4: Wk7 | M4: Wk8 | N4: Wk9 | O4: Wk10 | P4: Wk11 | Q4: Wk12 | R4: Wk13 | S4: Wk14 | T4: Wk15 | U4: Wk15 | V4: Wk17 | W4: Wk18 | X4: Wk19 | Y4: Wk20 | Z4: Wk21 | AA4: Wk22 | AB4: Wk23 | AC4: Wk24 | AD4: Wk25 | AE4: Wk26 | AF4: Wk27 | AG4: Wk28 | AH4: Wk29 | AI4: Wk30 | AJ4: Wk31 | AK4: Wk32 | AL4: Wk33 | AM4: Wk34 | AN4: Wk35 | AO4: Wk36 | AP4: Wk37 | AQ4: Wk38 | AR4: Wk39 | AS4: Wk40 | AT4: Wk41 | AU4: Wk42 | AV4: Wk43 | AW4: Wk44 | AX4: Wk45 | AY4: Wk46 | AZ4: Wk47
F5: 46041 | G5: =+F5+7 -> 46048 | H5: =+G5+7 -> 46055 | I5: =+H5+7 -> 46062 | J5: =+I5+7 -> 46069 | K5: =+J5+7 -> 46076 | L5: =+K5+7 -> 46083 | M5: =+L5+7 -> 46090 | N5: =+M5+7 -> 46097 | ... AZ5: =+AY5+7 -> 46363
F6: 46045 | G6: =+F6+7 -> 46052 | H6: =+G6+7 -> 46059 | I6: =+H6+7 -> 46066 | J6: =+I6+7 -> 46073 | K6: =+J6+7 -> 46080 | L6: =+K6+7 -> 46087 | M6: =+L6+7 -> 46094 | N6: =+M6+7 -> 46101 | ... AZ6: =+AY6+7 -> 46367
A7: Project/Phase | B7: Owner | C7: Status | D7: Start Date | E7: End Date
A8: P0 Attributes
A9: P0 Attributes - Refactoring | B9: Databricks | C9: Complete | D9: 46041 | E9: 46052
A10: P0 Data Quality validation | B10: L'Oreal IT | C10: Complete | D10: 46041 | E10: 46052
A11: P0 Data quality remediation | B11: Databricks | C11: Complete | D11: 46041 | E11: 46052
A12: P0 Deploy to Staging / Production Wave 1 | B12: L'Oreal IT | C12: Complete | D12: 46041 | E12: 46052 | F12: * Go Live
A13: P0 Deploy to Staging / Production Wave 2 | B13: L'Oreal IT | C13: Complete | D13: 46041 | E13: 46052 | G13: * Go Live
A14: P0 - Available for CDP in Prod | B14: Sapient | C14: Complete | D14: 46041 | E14: 46052
A16: P1 , P2 Attributes and Bar Activation KPIs
A17: Sprint 1
A18: Sprint 1 Refactoring (Domains: P1 ) | B18: Databricks | C18: Complete | D18: 46041 | E18: 46052
A19: Sprint 1 - IT DQ validation | B19: L'Oreal IT | C19: In-Progress | D19: 46055 | E19: 13-Feb
A20: Sprint 1 - CDMO DQ validation | B20: L'Oreal CDMO | C20: In-Progress | D20: 46055 | E20: 13-Feb
A21: Sprint 1 - DQ remediation ( Fix All defects and feedback | B21: Databricks | C21: In-Progress | D21: 13-Feb | E21: 20-Feb
A22: Sprint 1 Sign off - ( Regression Test Loreal IT and CDMO) | B22: L'Oreal IT & CDMO | C22: Not Started | D22: 16-Feb | E22: 20-Feb
A23: Sprint 1 - Prod Deployment | B23: Loreal IT | C23: Not Started | D23: 23-Feb | E23: 25-Feb | K23: * Go Live
A24: Sprint 1 - Available for CDP in Prod | B24: Sapient | C24: Not Started | D24: 46083 | E24: 46087
A26: Sprint 2
A27: Sprint 2 Refactoring (Domains: P1 ) | B27: Databricks | C27: Complete | D27: 2-Feb | E27: 13-Feb
A28: Sprint 2 - IT DQ validation | B28: L'Oreal IT | C28: In-Progress | D28: 16-Feb | E28: 27-Feb
A29: Sprint 2 - CDMO DQ validation | B29: L'Oreal IT | C29: In-Progress | D29: 16-Feb | E29: 27-Feb
A30: Sprint 2 - DQ remediation ( Fix All defects and feedback | B30: Databricks | C30: In-Progress | D30: 23-Feb | E30: 46087
A31: Sprint 2 Sign off - ( Regression Test Loreal IT and CDMO) | B31: L'Oreal IT & CDMO | C31: Not Started | D31: 46083 | E31: 46087
A32: Sprint 2 - Prod Deployment | B32: Loreal IT | C32: Not Started | D32: 46090 | E32: 46094 | M32: * Go Live
A33: Sprint 2 - Available for CDP in Prod | B33: Sapient | C33: Not Started | D33: 46097 | E33: 46108
A35: Sprint 3
A36: Sprint 3 Refactoring (Domains: P2 and Bar KPIs) | B36: Databricks | C36: In-Progress | D36: 16-Feb | E36: 27-Feb
A37: Sprint 3 - IT DQ validation | B37: L'Oreal IT | C37: Not Started | D37: 46083 | E37: 46094
A38: Sprint 3 - CDMO DQ validation | B38: L'Oreal IT | C38: Not Started | D38: 46083 | E38: 46094
A39: Sprint 3 - DQ remediation ( Fix All defects and feedback | B39: Databricks | C39: Not Started | D39: 46090 | E39: 46101
A40: Sprint 3 Sign off - ( Regression Test Loreal IT and CDMO) | B40: L'Oreal IT & CDMO | C40: Not Started | D40: 46097 | E40: 46101
A41: Sprint 3 - Prod Deployment | B41: Loreal IT | C41: Not Started | D41: 46104 | E41: 46108 | O41: * Go Live
A42: Sprint 3 - Available for CDP in Prod | B42: Sapient | C42: Not Started | D42: 46111 | E42: 46115
A44: Sprint 4
A45: Sprint 4 Refactoring (P2, Bar KPIs and chance to pull KPI Catalog) | B45: Databricks | C45: Not Started | D45: 46083 | E45: 46094
...

Sheet All Domains (Old Version)
D2: Please DO NOT sort column in default view - please create a separate view.
K3: Global Data Presence | N3: DDX Data Availability | Q3: Strategic Value & Activation | T3: Data Structure & Relationship | V3: Attribute Prioritization | AA3: Attribute Data Complexity | AC3: Pilot Use Case | AI3: Divisional Prioritization | AO3: WIP - JULIA
B4: Domain | C4: Sub-Domain | D4: Global Domain | E4: Global Sub Domain | F4: Business Term | G4: DDX Source Fields | H4: Reason For Review (Remove / Deprioritize) | I4: DDX Source Tables (Key DDX End Table Source of Truth) | J4: Business Definition | K4: In GDM Analytics Version? | L4: In Global One Consumer Profile? | M4: Exists in GDM | N4: In C360 Tables? | O4: In Glossary | P4: Exists in DDX | Q4: LiveRamp | R4: Attentive | S4: KPI | T4: Customer Relationship | U4: Domain Object Relationship | V4: Global One Consumer Profile Waves | W4: Priority | X4: Reason | Y4: First Pass Priority Level | Z4: Reason (from fist pass - ignore) | AA4: Data Complexities | AB4: Notes ( from Databricks) | AC4: LOP | AD4: SkinC | AE4: Valentino | AF4: Kerastase | AG4: Valentino Data Migration | AH4: In a Use Case? | AI4: CPD | AJ4: LDB | AK4: LUXE | AL4: PPD | AM4: ALL | AN4: ANY | AO4: Attribute Exists? | AP4: Planned for Gold Layer? | AQ4: Attribute Exists in Gold Layer?
B5: Customer | C5: BMDM (Beauty Data) | D5: Beauty Profile | E5: Beauty Preference | F5: Colorful hair | G5: colorful_hair | I5: crm_base.customer360 | J5: Blue, Pink, Green, Red, Yellow, Purple, Rainbow, Multiple | K5: N | L5: Y | M5: Y | N5: Y | O5: Y | P5: Y | Q5: Y | S5: N | T5: one-to-one | U5: one-to-one | V5: BPD | W5: 0 | X5: Use Case (Sapient) | Y5: N/A | Z5: DDX | AA5: Already have | AF5: X | AH5: =IF(OR(AC5="X", AD5 = "X", AE5="X", AF5="X", AG5="X"), "Y", "") -> Y | AI5: Y | AM5: =AND(AI5="Y",AJ5="Y",AK5="Y",AL5="Y") -> FALSE | AN5: =OR(AI5="Y",AJ5="Y",AK5="Y",AL5="Y") -> TRUE | AO5: Y
B6: Customer | C6: BMDM (Beauty Data) | D6: Beauty Profile | E6: Priorities | F6: Concern | G6: concern_improvement_goal | H6: LUXE Priority | I6: crm_base.customer360 | J6: Concern improvement goal | K6: N | L6: Y | M6: Y | N6: Y | O6: Y | P6: Y | Q6: Y | S6: N | T6: one-to-one | U6: one-to-one | V6: BPP | W6: 0 | X6: Use Case | Y6: 1 | Z6: DDX | AA6: Already have | AE6: X | AF6: X | AH6: =IF(OR(AC6="X", AD6 = "X", AE6="X", AF6="X", AG6="X"), "Y", "") -> Y | AI6: Y | AJ6: Y | AK6: Y | AL6: Y | AM6: =AND(AI6="Y",AJ6="Y",AK6="Y",AL6="Y") -> TRUE | AN6: =OR(AI6="Y",AJ6="Y",AK6="Y",AL6="Y") -> TRUE | AO6: Y
B7: Customer | C7: BMDM (Beauty Data) | D7: Beauty Profile | E7: N/A | F7: curls texture | G7: curls_texture | I7: crm_base.customer360 | J7: Curls texture of the customer | K7: N | L7: N | M7: N | N7: Y | O7: Y | P7: Y | Q7: Y | S7: N | T7: one-to-one | U7: one-to-one | W7: 0 | X7: Use Case | Y7: 1 | Z7: In Global One Consumer Profile & GDM Analytics | AA7: Already have | AF7: X | AH7: =IF(OR(AC7="X", AD7 = "X", AE7="X", AF7="X", AG7="X"), "Y", "") -> Y | AI7: Y | AL7: Y | AM7: =AND(AI7="Y",AJ7="Y",AK7="Y",AL7="Y") -> FALSE | AN7: =OR(AI7="Y",AJ7="Y",AK7="Y",AL7="Y") -> TRUE | AO7: Y
B8: Customer | C8: BMDM (Beauty Data) | D8: Beauty Profile | E8: N/A | F8: drugstore preference | G8: drugstore | H8: more data here | I8: crm_base.customer360 | J8: CVS, Walgreens | K8: N | L8: N | M8: N | N8: Y | O8: Y | P8: Y | Q8: Y | S8: N | T8: one-to-one | U8: one-to-one | W8: 1 | X8: Liveramp | Y8: 2 | Z8: In GDM & C360 | AA8: Already have | AH8: =IF(OR(AC8="X", AD8 = "X", AE8="X", AF8="X", AG8="X"), "Y", "") | AJ8: Y | AK8: Y | AL8: Y | AM8: =AND(AI8="Y",AJ8="Y",AK8="Y",AL8="Y") -> FALSE | AN8: =OR(AI8="Y",AJ8="Y",AK8="Y",AL8="Y") -> TRUE | AO8: Y
B9: Customer | C9: BMDM (Beauty Data) | D9: Beauty Profile | E9: Description | F9: Eye Color | G9: eye_color | I9: crm_base.customer360 | J9: Eye color of the customer | K9: N | L9: Y | M9: Y | N9: Y | O9: Y | P9: Y | Q9: Y | S9: N | T9: one-to-one | U9: one-to-one | V9: BPD | W9: 1 | X9: One Consumer Profile, C360, Liveramp | Y9: 2 | Z9: Need to Clarify with Global | AA9: Already have | AH9: =IF(OR(AC9="X", AD9 = "X", AE9="X", AF9="X", AG9="X"), "Y", "") | AK9: Y | AM9: =AND(AI9="Y",AJ9="Y",AK9="Y",AL9="Y") -> FALSE | AN9: =OR(AI9="Y",AJ9="Y",AK9="Y",AL9="Y") -> TRUE | AO9: Y
B10: Customer | C10: BMDM (Beauty Data) | D10: Beauty Profile | E10: N/A | F10: fragrance family | G10: fragrance_family | H10: LUXE Priority | I10: crm_base.customer360 | J10: Citrus, Floral, Fougere, Oriental, Woody, Musk, Chype | K10: N | L10: N | M10: N | N10: Y | O10: Y | P10: Y | Q10: Y | S10: N | T10: one-to-one | U10: one-to-one | W10: 0 | X10: Use Case | Y10: 1 | Z10: In GDM & C360 | AA10: Already have | AE10: X | AH10: =IF(OR(AC10="X", AD10 = "X", AE10="X", AF10="X", AG10="X"), "Y", "") -> Y | AK10: Y | AM10: =AND(AI10="Y",AJ10="Y",AK10="Y",AL10="Y") -> FALSE | AN10: =OR(AI10="Y",AJ10="Y",AK10="Y",AL10="Y") -> TRUE | AO10: Y
B11: Customer | C11: BMDM (Beauty Data) | D11: Beauty Profile | E11: N/A | F11: fragrance note | G11: fragrance_note | I11: crm_base.customer360 | J11: Aqua, Green, Aromatic, Fruity, White floral, Rose, Violet, Musk, Power musk, Leather, Amber, Spicy | K11: N | L11: N | M11: N | N11: Y | O11: Y | P11: Y | Q11: Y | S11: N | T11: one-to-one | U11: one-to-one | W11: 0 | X11: Use Case | Y11: 1 | Z11: In GDM & C360 | AA11: Already have | AE11: X | AH11: =IF(OR(AC11="X", AD11 = "X", AE11="X", AF11="X", AG11="X"), "Y", "") -> Y | AK11: Y | AM11: =AND(AI11="Y",AJ11="Y",AK11="Y",AL11="Y") -> FALSE | AN11: =OR(AI11="Y",AJ11="Y",AK11="Y",AL11="Y") -> TRUE | AO11: Y
B12: Customer | C12: BMDM (Beauty Data) | D12: Beauty Profile | E12: N/A | F12: grocery store/supermarket preference | G12: grocery_supermarket | H12: cvs, kroger, ulta | I12: crm_base.customer360 | J12: Grocery Supermarket | K12: N | L12: N | M12: N | N12: Y | O12: Y | P12: Y | Q12: Y | S12: N | T12: one-to-one | U12: one-to-one | W12: 1 | X12: One Consumer Profile, C360, Liveramp | Y12: 1 | Z12: In GDM & C360 | AA12: Already have | AH12: =IF(OR(AC12="X", AD12 = "X", AE12="X", AF12="X", AG12="X"), "Y", "") | AK12: Y | AL12: Y | AM12: =AND(AI12="Y",AJ12="Y",AK12="Y",AL12="Y") -> FALSE | AN12: =OR(AI12="Y",AJ12="Y",AK12="Y",AL12="Y") -> TRUE | AO12: Y
B13: Customer | C13: BMDM (Beauty Data) | D13: Beauty Profile | E13: N/A | F13: hair care product | G13: hair_care_product | I13: crm_base.customer360 | J13: Hair care products | K13: N | L13: N | M13: N | N13: Y | O13: Y | P13: Y | Q13: Y | S13: N | T13: one-to-one | U13: one-to-one | W13: 0 | X13: Use Case | Y13: 1 | Z13: In GDM & C360 | AA13: Already have | AF13: X | AH13: =IF(OR(AC13="X", AD13 = "X", AE13="X", AF13="X", AG13="X"), "Y", "") -> Y | AL13: Y | AM13: =AND(AI13="Y",AJ13="Y",AK13="Y",AL13="Y") -> FALSE | AN13: =OR(AI13="Y",AJ13="Y",AK13="Y",AL13="Y") -> TRUE | AO13: Y
B14: Customer | C14: BMDM (Beauty Data) | D14: Beauty Profile | E14: Description | F14: Hair Color | G14: hair_color | I14: crm_base.customer360 | J14: Hair color of the customer | K14: N | L14: Y | M14: Y | N14: Y | O14: Y | P14: Y | Q14: Y | S14: N | T14: one-to-one | U14: one-to-one | V14: BPD | W14: 0 | X14: Use Case | Y14: 1 | Z14: In GDM & C360 | AA14: Already have | AF14: X | AH14: =IF(OR(AC14="X", AD14 = "X", AE14="X", AF14="X", AG14="X"), "Y", "") -> Y | AI14: Y | AJ14: Y | AL14: Y | AM14: =AND(AI14="Y",AJ14="Y",AK14="Y",AL14="Y") -> FALSE | AN14: =OR(AI14="Y",AJ14="Y",AK14="Y",AL14="Y") -> TRUE | AO14: Y
B15: Customer | C15: BMDM (Beauty Data) | D15: Beauty Profile | E15: N/A | F15: hair color cover | G15: hair_color_cover | I15: crm_base.customer360 | J15: Hair color cover | K15: N | L15: N | M15: N | N15: Y | O15: Y | P15: Y | Q15: Y | S15: N | T15: one-to-one | U15: one-to-one | W15: 0 | X15: Use Case | Y15: 1 | Z15: In GDM & C360 | AA15: Already have | AF15: X | AH15: =IF(OR(AC15="X", AD15 = "X", AE15="X", AF15="X", AG15="X"), "Y", "") -> Y | AI15: Y | AL15: Y | AM15: =AND(AI15="Y",AJ15="Y",AK15="Y",AL15="Y") -> FALSE | AN15: =OR(AI15="Y",AJ15="Y",AK15="Y",AL15="Y") -> TRUE | AO15: Y
B16: Customer | C16: BMDM (Beauty Data) | D16: Beauty Profile | E16: N/A | F16: hair color finish | G16: hair_color_finish | I16: prod_us_catalog.crm_base.fact_gdm_beauty_profile | J16: Hair color finish | K16: N | L16: N | M16: N | N16: Y | O16: Y | P16: Y | S16: N | T16: one-to-one | U16: one-to-one | W16: 1 | X16: One Consumer Profile, C360 | Y16: 1 | Z16: Need to Clarify with Global | AA16: Easy Add | AB16: in crm_base.fact_gdm_beauty_profile | AH16: =IF(OR(AC16="X", AD16 = "X", AE16="X", AF16="X", AG16="X"), "Y", "") | AL16: Y | AM16: =AND(AI16="Y",AJ16="Y",AK16="Y",AL16="Y") -> FALSE | AN16: =OR(AI16="Y",AJ16="Y",AK16="Y",AL16="Y") -> TRUE | AO16: Y
B17: Customer | C17: BMDM (Beauty Data) | D17: Beauty Profile | E17: N/A | F17: hair color service | G17: hair_color_service | I17: crm_base.customer360 | J17: Hair color service | K17: N | L17: N | M17: N | N17: Y | O17: Y | P17: Y | Q17: Y | S17: N | T17: one-to-one | U17: one-to-one | W17: 0 | X17: Use Case | Y17: 1 | Z17: In GDM & C360 | AA17: Already have | AF17: X | AH17: =IF(OR(AC17="X", AD17 = "X", AE17="X", AF17="X", AG17="X"), "Y", "") -> Y | AI17: Y | AL17: Y | AM17: =AND(AI17="Y",AJ17="Y",AK17="Y",AL17="Y") -> FALSE | AN17: =OR(AI17="Y",AJ17="Y",AK17="Y",AL17="Y") -> TRUE | AO17: Y
B18: Customer | C18: BMDM (Beauty Data) | D18: Beauty Profile | E18: Description | F18: Hair state | G18: hair_state | I18: crm_base.customer360 | J18: Straight, Wavy, Loose waves, Curls, Curly, Coily, Kinky, Frizzy, Tight Curls | K18: N | L18: Y | M18: Y | N18: Y | O18: Y | P18: Y | Q18: Y | S18: N | T18: one-to-one | U18: one-to-one | V18: 0 | W18: 0 | X18: Use Case | Y18: 1 | Z18: Need to Clarify with Global | AA18: Already have | AE18: X | AF18: X | AH18: =IF(OR(AC18="X", AD18 = "X", AE18="X", AF18="X", AG18="X"), "Y", "") -> Y | AI18: Y | AJ18: Y | AM18: =AND(AI18="Y",AJ18="Y",AK18="Y",AL18="Y") -> FALSE | AN18: =OR(AI18="Y",AJ18="Y",AK18="Y",AL18="Y") -> TRUE | AO18: Y
B19: Customer | C19: BMDM (Beauty Data) | D19: Beauty Profile | E19: N/A | F19: hair style service | G19: hair_style_service | I19: crm_base.customer360 | J19: Straightener, Brazilian keratin treatment, Perm, Relaxer, None | K19: N | L19: N | M19: N | N19: Y | O19: Y | P19: Y | Q19: Y | S19: N | T19: one-to-one | U19: one-to-one | W19: 0 | X19: Use Case | Y19: 1 | Z19: Need Info from Global | AA19: Already have | AH19: =IF(OR(AC19="X", AD19 = "X", AE19="X", AF19="X", AG19="X"), "Y", "") | AL19: Y | AM19: =AND(AI19="Y",AJ19="Y",AK19="Y",AL19="Y") -> FALSE | AN19: =OR(AI19="Y",AJ19="Y",AK19="Y",AL19="Y") -> TRUE | AO19: Y
B20: Customer | C20: BMDM (Beauty Data) | D20: Beauty Profile | E20: Description | F20: Hair texture | G20: hair_texture | I20: crm_base.customer360 | J20: Hair texture of the customer: Thin, Medium, Normal, Coarse, Thick, Don't Know | K20: N | L20: Y | M20: Y | N20: Y | O20: Y | P20: Y | Q20: Y | S20: N | T20: one-to-one | U20: one-to-one | V20: BPD | W20: 0 | X20: Use Case | Y20: 1 | Z20: Need info from Global | AA20: Already have | AE20: X | AF20: X | AH20: =IF(OR(AC20="X", AD20 = "X", AE20="X", AF20="X", AG20="X"), "Y", "") -> Y | AJ20: Y | AM20: =AND(AI20="Y",AJ20="Y",AK20="Y",AL20="Y") -> FALSE | AN20: =OR(AI20="Y",AJ20="Y",AK20="Y",AL20="Y") -> TRUE | AO20: Y
B21: Customer | C21: BMDM (Beauty Data) | D21: Beauty Profile | E21: N/A | F21: hair treatment | G21: hair_treatment | I21: prod_us_catalog.crm_base.fact_gdm_beauty_profile | K21: N | L21: N | M21: N | N21: Y | O21: Y | P21: Y | S21: N | T21: one-to-one | U21: one-to-one | W21: 1 | X21: One Consumer Profile, C360 | Y21: 1 | Z21: Need info from Global | AA21: Easy Add | AB21: in crm_base.fact_gdm_beauty_profile | AH21: =IF(OR(AC21="X", AD21 = "X", AE21="X", AF21="X", AG21="X"), "Y", "") | AL21: Y | AM21: =AND(AI21="Y",AJ21="Y",AK21="Y",AL21="Y") -> FALSE | AN21: =OR(AI21="Y",AJ21="Y",AK21="Y",AL21="Y") -> TRUE | AO21: Y
B22: Customer | C22: BMDM (Beauty Data) | D22: Beauty Profile | E22: Description | F22: Hair type | G22: hair_type | I22: crm_base.customer360 | J22: Very Dry, Somewhat Dry, Normal, Somewhat Oily, Somewhat greasy, Very Oily, Very greasy, Combination, Greasy roots and dry ends, Don't Know | K22: N | L22: Y | M22: Y | N22: Y | O22: Y | P22: Y | Q22: Y | S22: N | T22: one-to-one | U22: one-to-one | V22: BPD | W22: 0 | X22: Use Case (Sapient) | Y22: 1 | Z22: DDX & Global One Consumer Data Profile | AA22: Already have | AB22: in customer_profile | AF22: X | AH22: =IF(OR(AC22="X", AD22 = "X", AE22="X", AF22="X", AG22="X"), "Y", "") -> Y | AI22: Y | AJ22: Y | AL22: Y | AM22: =AND(AI22="Y",AJ22="Y",AK22="Y",AL22="Y") -> FALSE | AN22: =OR(AI22="Y",AJ22="Y",AK22="Y",AL22="Y") -> TRUE | AO22: Y
B23: Customer | C23: BMDM (Beauty Data) | D23: Beauty Profile | E23: Routines | F23: Hair wash frequency | G23: hair_wash_frequency | I23: crm_base.customer360 | J23: Represents the frequency of hair washing, providing insights into hair care habits. | K23: N | L23: Y | M23: Y | N23: N | O23: Y | P23: Y | S23: N | T23: one-to-one | U23: one-to-one | V23: BPR | W23: 2 | X23: Global Request that we need to fulfil | Y23: 2 | Z23: In GDM & C360 | AA23: Easy Add | AB23: in crm_base.fact_gdm_beauty_profile | AH23: =IF(OR(AC23="X", AD23 = "X", AE23="X", AF23="X", AG23="X"), "Y", "") | AL23: Y | AM23: =AND(AI23="Y",AJ23="Y",AK23="Y",AL23="Y") -> FALSE | AN23: =OR(AI23="Y",AJ23="Y",AK23="Y",AL23="Y") -> TRUE | AO23: Y
B24: Customer | C24: BMDM (Beauty Data) | D24: Beauty Profile | E24: Routines | F24: Heating tool | G24: heating_tool | I24: crm_base.customer360 | K24: N | L24: Y | M24: Y | N24: N | O24: Y | P24: Y | S24: N | T24: one-to-one | U24: one-to-one | V24: BPR | W24: 1 | X24: One Consumer Profile, C360 | Y24: 1 | Z24: DDX & GDM Analytics | AA24: Easy Add | AB24: in crm_base.fact_gdm_beauty_profile | AH24: =IF(OR(AC24="X", AD24 = "X", AE24="X", AF24="X", AG24="X"), "Y", "") | AL24: Y | AM24: =AND(AI24="Y",AJ24="Y",AK24="Y",AL24="Y") -> FALSE | AN24: =OR(AI24="Y",AJ24="Y",AK24="Y",AL24="Y") -> TRUE | AO24: Y
B25: Customer | C25: BMDM (Beauty Data) | D25: Beauty Profile | E25: N/A | F25: lash look priority | G25: lash_look_priority | H25: LUXE Priority | I25: crm_base.customer360 | J25: Volume, Volumizing / Thickening, Length Lenghtening / Long lashes, Definition, Seperate lashes, Curl, Curling, Waterproof | K25: N | L25: N | M25: N | N25: Y | O25: Y | P25: Y | Q25: Y | S25: N | T25: one-to-one | U25: one-to-one | W25: 1 | X25: TransUnion | Y25: 1 | Z25: DDX & GDM Analytics | AA25: Already have | AH25: =IF(OR(AC25="X", AD25 = "X", AE25="X", AF25="X", AG25="X"), "Y", "") | AK25: Y | AM25: =AND(AI25="Y",AJ25="Y",AK25="Y",AL25="Y") -> FALSE | AN25: =OR(AI25="Y",AJ25="Y",AK25="Y",AL25="Y") -> TRUE | AO25: Y
B26: Customer | C26: BMDM (Beauty Data) | D26: Beauty Profile | E26: N/A | F26: makeup expectation | G26: makeup_expectation | I26: crm_base.customer360 | J26: Makeup Expectation of the customer | K26: N | L26: N | M26: N | N26: Y | O26: Y | P26: Y | Q26: Y | S26: N | T26: one-to-one | U26: one-to-one | W26: 1 | X26: Liveramp | Y26: 2 | Z26: DDX & Global One Consumer Data Profile | AA26: Already have | AH26: =IF(OR(AC26="X", AD26 = "X", AE26="X", AF26="X", AG26="X"), "Y", "") | AI26: Y | AM26: =AND(AI26="Y",AJ26="Y",AK26="Y",AL26="Y") -> FALSE | AN26: =OR(AI26="Y",AJ26="Y",AK26="Y",AL26="Y") -> TRUE | AO26: Y
B27: Customer | C27: BMDM (Beauty Data) | D27: Beauty Profile | E27: N/A | F27: makeup look | G27: makeup_look | H27: LUXE Priority | I27: crm_base.customer360 | J27: Make up look | K27: N | L27: N | M27: N | N27: Y | O27: Y | P27: Y | Q27: Y | S27: N | T27: one-to-one | U27: one-to-one | W27: 1 | X27: GDM Analytics | Y27: 2 | Z27: In GDM & C360 | AA27: Already have | AH27: =IF(OR(AC27="X", AD27 = "X", AE27="X", AF27="X", AG27="X"), "Y", "") | AI27: Y | AK27: Y | AM27: =AND(AI27="Y",AJ27="Y",AK27="Y",AL27="Y") -> FALSE | AN27: =OR(AI27="Y",AJ27="Y",AK27="Y",AL27="Y") -> TRUE | AO27: Y
B28: Customer | C28: BMDM (Beauty Data) | D28: Beauty Profile | E28: N/A | F28: makeup skill level | G28: makeup_skill_level | I28: crm_base.customer360 | J28: Make up skill level | K28: N | L28: N | M28: N | N28: Y | O28: Y | P28: Y | Q28: Y | S28: N | T28: one-to-one | U28: one-to-one | W28: 1 | X28: GDM Analytics | Y28: 1 | Z28: DDX & GDM Analytics | AA28: Already have | AH28: =IF(OR(AC28="X", AD28 = "X", AE28="X", AF28="X", AG28="X"), "Y", "") | AI28: Y | AM28: =AND(AI28="Y",AJ28="Y",AK28="Y",AL28="Y") -> FALSE | AN28: =OR(AI28="Y",AJ28="Y",AK28="Y",AL28="Y") -> TRUE | AO28: Y
B29: Customer | C29: BMDM (Beauty Data) | D29: Beauty Profile | E29: N/A | F29: nail aesthetic | G29: nail_aesthetic | I29: crm_base.customer360 | J29: Nail Aesthetic | K29: N | L29: N | M29: N | N29: Y | O29: Y | P29: Y | Q29: Y | S29: N | T29: one-to-one | U29: one-to-one | W29: 1 | X29: GDM Analytics | Y29: 1 | Z29: DDX & GDM Analytics | AA29: Already have | AH29: =IF(OR(AC29="X", AD29 = "X", AE29="X", AF29="X", AG29="X"), "Y", "") | AI29: Y | AM29: =AND(AI29="Y",AJ29="Y",AK29="Y",AL29="Y") -> FALSE | AN29: =OR(AI29="Y",AJ29="Y",AK29="Y",AL29="Y") -> TRUE | AO29: Y
B30: Customer | C30: BMDM (Beauty Data) | D30: Beauty Profile | E30: N/A | F30: nail color | G30: nail_color | I30: crm_base.customer360 | J30: Nail color of the customer | K30: N | L30: N | M30: N | N30: Y | O30: Y | P30: Y | Q30: Y | S30: N | T30: one-to-one | U30: one-to-one | W30: 1 | X30: Prioritized by Division(s) | Y30: 2 | Z30: Not in C360, reporting | AA30: Already have | AH30: =IF(OR(AC30="X", AD30 = "X", AE30="X", AF30="X", AG30="X"), "Y", "") | AI30: Y | AM30: =AND(AI30="Y",AJ30="Y",AK30="Y",AL30="Y") -> FALSE | AN30: =OR(AI30="Y",AJ30="Y",AK30="Y",AL30="Y") -> TRUE | AO30: Y
B31: Customer | C31: BMDM (Beauty Data) | D31: Beauty Profile | E31: N/A | F31: nail skill level | G31: nail_skill_level | I31: crm_base.customer360 | J31: Nail skill level | K31: N | L31: N | M31: N | N31: Y | O31: Y | P31: Y | Q31: Y | S31: N | T31: one-to-one | U31: one-to-one | W31: 1 | X31: Prioritized by Division(s) | Y31: 2 | Z31: In GDM & C360 | AA31: Already have | AH31: =IF(OR(AC31="X", AD31 = "X", AE31="X", AF31="X", AG31="X"), "Y", "") | AI31: Y | AM31: =AND(AI31="Y",AJ31="Y",AK31="Y",AL31="Y") -> FALSE | AN31: =OR(AI31="Y",AJ31="Y",AK31="Y",AL31="Y") -> TRUE | AO31: Y
B32: Customer | C32: BMDM (Beauty Data) | D32: Beauty Profile | E32: N/A | F32: pro teatments | G32: pro_treatments | I32: prod_us_catalog.crm_base.fact_gdm_beauty_profile | J32: Pro treatments | K32: N | L32: N | M32: N | N32: Y | O32: Y | P32: Y | S32: N | T32: one-to-one | U32: one-to-one | W32: 1 | X32: One Consumer Profile & C360 | Y32: 1 | Z32: Not in C360, no waves, reporting | AA32: Easy Add | AB32: in crm_base.fact_gdm_beauty_profile | AH32: =IF(OR(AC32="X", AD32 = "X", AE32="X", AF32="X", AG32="X"), "Y", "") | AJ32: Y | AM32: =AND(AI32="Y",AJ32="Y",AK32="Y",AL32="Y") -> FALSE | AN32: =OR(AI32="Y",AJ32="Y",AK32="Y",AL32="Y") -> TRUE | AO32: Y
B33: Customer | C33: BMDM (Beauty Data) | D33: Beauty Profile | E33: N/A | F33: pro treatment regimen | G33: pro_treatment_regimen | I33: prod_us_catalog.crm_base.fact_gdm_beauty_profile | J33: Pro Treatment regimen | K33: N | L33: N | M33: N | N33: Y | O33: Y | P33: Y | S33: N | T33: one-to-one | U33: one-to-one | W33: 1 | X33: One Consumer Profile, C360 | Y33: 1 | Z33: Not in C360, no waves, reporting | AA33: Easy Add | AB33: in crm_base.fact_gdm_beauty_profile | AH33: =IF(OR(AC33="X", AD33 = "X", AE33="X", AF33="X", AG33="X"), "Y", "") | AJ33: Y | AM33: =AND(AI33="Y",AJ33="Y",AK33="Y",AL33="Y") -> FALSE | AN33: =OR(AI33="Y",AJ33="Y",AK33="Y",AL33="Y") -> TRUE | AO33: Y
B34: Customer | C34: BMDM (Beauty Data) | D34: Beauty Profile | E34: N/A | F34: product category | G34: product_category | H34: LUXE Priority | I34: crm_base.customer360 | J34: Product category | K34: N | L34: N | M34: N | N34: Y | O34: Y | P34: Y | Q34: Y | S34: N | T34: one-to-one | U34: one-to-one | W34: 0 | X34: Use Case | Y34: 1 | AA34: Already have | AE34: X | AF34: X | AH34: =IF(OR(AC34="X", AD34 = "X", AE34="X", AF34="X", AG34="X"), "Y", "") -> Y | AI34: Y | AJ34: Y | AM34: =AND(AI34="Y",AJ34="Y",AK34="Y",AL34="Y") -> FALSE | AN34: =OR(AI34="Y",AJ34="Y",AK34="Y",AL34="Y") -> TRUE | AO34: Y
B35: Customer | C35: BMDM (Beauty Data) | D35: Beauty Profile | E35: N/A | F35: product coverage | G35: product_coverage | I35: crm_base.customer360 | J35: Product coverage | K35: N | L35: N | M35: N | N35: Y | O35: Y | P35: Y | Q35: Y | S35: N | T35: one-to-one | U35: one-to-one | W35: 0 | X35: Use Case | Y35: 1 | Z35: Reporting | AA35: Already have | AH35: =IF(OR(AC35="X", AD35 = "X", AE35="X", AF35="X", AG35="X"), "Y", "") | AK35: Y | AM35: =AND(AI35="Y",AJ35="Y",AK35="Y",AL35="Y") -> FALSE | AN35: =OR(AI35="Y",AJ35="Y",AK35="Y",AL35="Y") -> TRUE | AO35: Y
B36: Customer | C36: BMDM (Beauty Data) | D36: Beauty Profile | E36: N/A | F36: product finish | G36: product_finish | H36: LUXE Priority | I36: crm_base.customer360 | J36: Describes the finish of the product, such as matte, glossy, or semi-matte. | K36: N | L36: N | M36: N | N36: Y | O36: Y | P36: Y | Q36: Y | S36: N | T36: one-to-one | U36: one-to-one | W36: 1 | X36: One Consumer Profile, C360, Liveramp | Y36: 1 | Z36: Not in C360, reporting | AA36: Already have | AF36: X | AH36: =IF(OR(AC36="X", AD36 = "X", AE36="X", AF36="X", AG36="X"), "Y", "") -> Y | AM36: =AND(AI36="Y",AJ36="Y",AK36="Y",AL36="Y") -> FALSE | AN36: =OR(AI36="Y",AJ36="Y",AK36="Y",AL36="Y") -> FALSE | AO36: Y
B37: Customer | C37: BMDM (Beauty Data) | D37: Beauty Profile | E37: Recommendation | F37: Product Recommendation | G37: N/A | H37: Talking to Grant 11/13 | I37: N/A | J37: Consumer product recommendation | K37: Y | L37: Y | M37: Y | N37: N | O37: N | P37: N | S37: N | T37: one-to-one | U37: one-to-one | V37: PRD | W37: 2 | X37: No Use Case | Y37: 1 | Z37: Not in C360, no waves, reporting | AH37: =IF(OR(AC37="X", AD37 = "X", AE37="X", AF37="X", AG37="X"), "Y", "") | AI37: N/A | AJ37: N/A | AK37: N/A | AL37: N/A | AM37: =AND(AI37="Y",AJ37="Y",AK37="Y",AL37="Y") -> FALSE | AN37: =OR(AI37="Y",AJ37="Y",AK37="Y",AL37="Y") -> FALSE | AO37: Y
B38: Customer | C38: BMDM (Beauty Data) | D38: Beauty Profile | E38: N/A | F38: product type | G38: product_type | I38: crm_base.customer360 | J38: Product type | K38: N | L38: N | M38: N | N38: Y | O38: Y | P38: Y | Q38: Y | S38: N | T38: one-to-one | U38: one-to-one | W38: 0 | X38: Use Case | Y38: 1 | Z38: Reporting | AA38: Already have | AH38: =IF(OR(AC38="X", AD38 = "X", AE38="X", AF38="X", AG38="X"), "Y", "") | AI38: Y | AM38: =AND(AI38="Y",AJ38="Y",AK38="Y",AL38="Y") -> FALSE | AN38: =OR(AI38="Y",AJ38="Y",AK38="Y",AL38="Y") -> TRUE | AO38: Y
B39: Customer | C39: BMDM (Beauty Data) | D39: Beauty Profile | E39: N/A | F39: pure player preference | G39: pure_players | I39: crm_base.customer360 | J39: Amazon, Ebay, Jet | K39: N | L39: N | M39: N | N39: Y | O39: Y | P39: Y | Q39: Y | S39: N | T39: one-to-one | U39: one-to-one | W39: 0 | X39: Use Case | Y39: 1 | Z39: Not in C360, reporting | AA39: Already have | AH39: =IF(OR(AC39="X", AD39 = "X", AE39="X", AF39="X", AG39="X"), "Y", "") | AL39: Y | AM39: =AND(AI39="Y",AJ39="Y",AK39="Y",AL39="Y") -> FALSE | AN39: =OR(AI39="Y",AJ39="Y",AK39="Y",AL39="Y") -> TRUE | AO39: Y
B40: Customer | C40: BMDM (Beauty Data) | D40: Beauty Profile | E40: Description | F40: Scalp type | G40: scalp_type | I40: crm_base.customer360 | J40: Very Dry, Somewhat Dry, Normal, Somewhat Oily, Somewhat greasy, Very Oily, Greasy scalp, Don’t Know | K40: N | L40: Y | M40: Y | N40: Y | O40: Y | P40: Y | Q40: Y | S40: N | T40: one-to-one | U40: one-to-one | V40: BPD | W40: 0 | X40: Use Case | Y40: 1 | Z40: In GDM & C360 | AA40: Already have | AE40: X | AF40: X | AH40: =IF(OR(AC40="X", AD40 = "X", AE40="X", AF40="X", AG40="X"), "Y", "") -> Y | AJ40: Y | AL40: Y | AM40: =AND(AI40="Y",AJ40="Y",AK40="Y",AL40="Y") -> FALSE | AN40: =OR(AI40="Y",AJ40="Y",AK40="Y",AL40="Y") -> TRUE | AO40: Y
B41: Customer | C41: BMDM (Beauty Data) | D41: Beauty Profile | E41: Description | F41: Skin tone | G41: skin_tone | H41: LUXE Priority | I41: crm_base.customer360 | J41: Skin tone of the customer. Possible Values- Light, Fair, Medium, Tan, Brown, Very deep, Black, Don't Know | K41: N | L41: Y | M41: Y | N41: Y | O41: Y | P41: Y | Q41: Y | S41: N | T41: one-to-one | U41: one-to-one | V41: BPD | W41: 1 | X41: No Use Case | Y41: 2 | Z41: Not in C360, no waves, reporting | AA41: Already have | AF41: X | AH41: =IF(OR(AC41="X", AD41 = "X", AE41="X", AF41="X", AG41="X"), "Y", "") -> Y | AI41: Y | AJ41: Y | AK41: Y | AM41: =AND(AI41="Y",AJ41="Y",AK41="Y",AL41="Y") -> FALSE | AN41: =OR(AI41="Y",AJ41="Y",AK41="Y",AL41="Y") -> TRUE | AO41: Y
...

Sheet Customer
B2: Sub-Domain | C2: Source fields | D2: Source tables (Key DDX end table source of truth) | E2: In GDM Analytics Version? | F2: In GDM Activation Version? | G2: In C360 Tables? | H2: In Glossary? | I2: KPI? | J2: Customer Relationship | K2: Definition
B3: Identity | C3: brand_customer_id | D3: crm_reporting.fact_customer_segment_by_brand_latest_snap | E3: Y | F3: Y | H3: Y | J3: one-to-one
B4: Identity | C4: brand_mdm_id | D4: crm_reporting.fact_customer_segment_by_brand_latest_snap | G4: Y | H4: Y | J4: one-to-one | K4: Identifier for the customer associated with the brand, allowing tracking of brand-specific customer information
B5: Identity | C5: ekey | D5: crm_reporting.vw_dp_neustar_customer | H5: Y | J5: one-to-one | K5: TransUnion unique consumer identifier (to be leveraged for identity resolution)
B6: Identity | C6: brand_code | D6: crm_base.customer360 | E6: Y | F6: Y | G6: Y | H6: Y | J6: one-to-one | K6: Specifies the brand_code to which the customer belongs
B7: Identity | C7: division_code | D7: crm_base.customer360 | E7: Y | F7: Y | G7: Y | H7: Y | J7: one-to-one | K7: Specifies the division to which the customer belongs
B8: Identity | C8: country_code | D8: crm_reporting.fact_customer_segment_by_brand_latest_snap | E8: Y | F8: Y | H8: Y | J8: one-to-one | K8: Country code of the customer address
B9: Identity | C9: first_name | D9: crm_base.customer360 | F9: Y | G9: Y | H9: Y | J9: one-to-one | K9: The customer's first name
B10: Identity | C10: last_name | D10: crm_base.customer360 | F10: Y | G10: Y | H10: Y | J10: one-to-one | K10: The customer's last name
B11: Identity | C11: birth_month_day | D11: crm_base.customer360 | E11: Y | F11: Y | G11: Y | H11: Y | J11: one-to-one | K11: Specifies the customer's birth month and day
B12: Identity | C12: gender | D12: crm_reporting.fact_customer_segment_by_brand_latest_snap | E12: Y | F12: Y | H12: Y | J12: one-to-one | K12: Specifies the gender of the customer
B13: Identity | C13: segment_name | D13: crm_base.customer360 | G13: Y | H13: Y | J13: one-to-one | K13: Name of the customer's sociovision segment
B14: Identity | C14: ltfg | D14: crm_base.customer360 | G14: Y | H14: Y | J14: one-to-one | K14: Indicates whether the customer is part of our long term frozen control group (ltfg) for A/B testing
B15: Identity | C15: last_modified_dt | D15: crm_base.customer360 | E15: Y | F15: Y | G15: Y | H15: Y | J15: one-to-one | K15: Specifies the date the customer's profile was last modified
B16: Identity | C16: IsControl | D16: ADD US GDM SOURCE TABLES | E16: Y | F16: Y | H16: Y | J16: one-to-one | K16: Consumer is in a global control group
B17: Identity | C17: effective_start_dt | D17: crm_reporting.customer_control_grp | E17: Y | F17: Y | J17: one-to-one | K17: Date which the consumer was placed in a global control group
B18: Identity | C18: effective_end_dt | D18: crm_reporting.customer_control_grp | E18: Y | F18: Y | J18: one-to-one | K18: Date which the consumer was removed from a global control group
B19: Contactability | C19: contactability_key | D19: crm_base.customer360 | E19: Y | F19: Y | G19: Y | H19: Y | J19: one-to-one | K19: Indicates whether the customer can be contacted through email, direct mail or both If email_perm_status=’OPTIN’ AND address_perm_status!=’OPTIN’ AND phone_perm_status!=’OPTIN’ Then ‘CONEML’ If email_perm_status!=’OPTIN’ AND address_perm_staus!=’OPTIN’ AND phone_perm_status=’OPTIN’ Then ‘CONPHN’ If email_perm_status!=’OPTIN’ ANDa address_perm_status=’OPTIN’ AND phone_perm_status!=’OPTIN’ THEN ‘CONDML’ If email_perm_status=’OPTIN’ AND address_perm_status=’OPTIN’ AND phone_perm_status!=’OPTIN’ THEN ‘CONEMLDML’ If email_perm_status=’OPTIN’ AND address_perm_status!=’OPTIN’ AND phone_perm_status=’OPTIN’ THEN ‘CONEMLPHN’ If email_perm_status!=’OPTIN’ AND address_perm_status=’OPTIN’ AND phone_perm_status=’OPTIN’ THEN ‘CONDMLPHN’
B20: Contactability | C20: email_perm_status | D20: crm_base.customer360 | E20: Y | F20: Y | G20: Y | H20: Y | J20: one-to-one | K20: Indicates if account/professional has given permission (subscribed) to contact her on the given email.
B21: Contactability | C21: sms_double_optin | D21: crm_reporting.fact_customer_segment_by_brand_latest_snap | E21: Y | F21: Y | H21: Y | J21: one-to-one | K21: Represents the permission status of SMS communication, indicating whether the customer has given permission to be contacted via SMS or not.
B22: Contactability | C22: phone_perm_status | D22: crm_reporting.fact_customer_segment_by_brand_latest_snap | E22: Y | F22: Y | H22: Y | J22: one-to-one | K22: Indicates if account/professional has given permission (subscribed) to contact her on the given phone no.
B23: Contactability | C23: address_perm_status | D23: crm_reporting.fact_customer_segment_by_brand_latest_snap | E23: Y | F23: Y | H23: Y | J23: one-to-one | K23: Specifies if the account/professional can be contacted through direct mail or not
B24: Contactability | C24: targeted_advertisement_flag | D24: crm_base.customer360 | G24: Y | H24: Y | J24: one-to-one | K24: Represents the permission status of targeted advertisement communication, indicating whether the customer has given permission to be contacted via targeted ads or not.
B25: Contactability | C25: ValidEmail | D25: ADD US GDM SOURCE TABLES | E25: Y | F25: Y | J25: one-to-one | K25: Indicates whether or not the customer record has a valid email address
B26: Contactability | C26: ValidMobileNumber | D26: ADD US GDM SOURCE TABLES | E26: Y | F26: Y | J26: one-to-one | K26: Indicates whether or not the customer record has a valid phone number
B27: Contactability | C27: ValidAddress | D27: ADD US GDM SOURCE TABLES | E27: Y | F27: Y | J27: one-to-one | K27: Indicates whether or not the customer record has a valid mailing address
B28: Acquisition Data | C28: source_name | D28: crm_base.customer360 | E28: Y | F28: Y | G28: Y | H28: Y | J28: one-to-one | K28: Originating source system where the customer was acquired
B29: Acquisition Data | C29: acq_source | D29: crm_base.customer360 | G29: Y | H29: Y | J29: one-to-one | K29: This indicates the source where the customer was acquired from. Possible values: Website, Mobile. For manual upload, the following are the list: PopUp Store Media Leads Events Exhibits Product Launch Grand Opening Sweepstakes White Label Store Event 3rd Party Social Rewards Name Capture Cards Product Inserts
B30: Acquisition Data | C30: acq_sub_source | D30: crm_base.customer360 | E30: Y | F30: Y | G30: Y | H30: Y | J30: one-to-one | K30: Refers to the sub source of the acquisition
B31: Acquisition Data | C31: acq_medium | D31: crm_base.customer360 | G31: Y | H31: Y | J31: one-to-one | K31: Acquisition medium
B32: Acquisition Data | C32: acquisition_channel_key | D32: crm_base.customer360 | E32: Y | F32: Y | G32: Y | H32: Y | J32: one-to-one | K32: This key is calculated based on the source at which the first engagement and the value is returned. UDF Logic to calculate acquisition channel: UDF receives all the interactions of the customer as Input. Input is divided into multiple lists as specified above. It retrieves the first record from the Profile Management list and retrieves the source name and acquisition source from the record. If the acquisition source is not empty or not null, then the source name is concatenated with acquisition source and the resultant value is returned, else if acquisition source is empty or null then the source name is returned. Note: If the resultant source name is ‘HARTEHANKS’ or ‘CRMLITE’ and if there is a record with the same interaction date with source name other than ‘HARTEHANKS’ or ‘CRMLITE’, then that record is considered as a priority.
B33: Acquisition Data | C33: acquisition_device_key | D33: crm_reporting.fact_customer_segment_by_brand_latest_snap | E33: Y | F33: Y | J33: one-to-one
B34: Acquisition Data | C34: registration_source | D34: crm_base.customer360 | F34: Y | G34: Y | H34: Y | J34: one-to-one | K34: refers to the source of registration
B35: Acquisition Data | C35: registration_sub_source | D35: crm_base.customer360 | F35: Y | G35: Y | H35: Y | J35: one-to-one | K35: Refers to the sub source of the registration
B36: Acquisition Data | C36: registration_status_key | D36: crm_base.customer360 | F36: Y | G36: Y | H36: Y | J36: one-to-one | K36: Refers to registration at the brand website or any other channel where account/professional registration is possible Registered, Not Registered
B37: Acquisition Data | C37: acquisition_date_key | D37: crm_base.customer360 | E37: Y | F37: Y | G37: Y | H37: Y | J37: one-to-one | K37: The date of the first profile management record of the customer. UDF Logic to calculate acquisition date: UDF receives all the interactions of the customer as Input. Input is divided into multiple lists as specified above. It retrieves the first record from the Profile Management list and retrieves the date from the record.
B38: Acquisition Data | C38: acquisition_source_type | D38: crm_base.dim_customer | E38: Y | F38: Y | H38: Y | J38: one-to-one
B39: Acquisition Data | C39: acquisition_source_touchpoint | D39: crm_base.dim_customer | E39: Y | F39: Y | H39: Y | J39: one-to-one
B40: Acquisition Data | C40: acquisition_source_channel | D40: crm_base.dim_customer | E40: Y | F40: Y | H40: Y | J40: one-to-one
B41: Acquisition Data | C41: acquisition_source_benefitid | D41: crm_base.dim_customer | E41: Y | F41: Y | H41: Y | J41: one-to-one
...

Sheet Contacts
B1: NOTE: We can choose to either represent contact info in its own table (following the C360 model) or reconfigure it within a customer entity table to be represented at the one-to-one level (ex. email1, email2...), accounting for customers having multiple emails, phone numbers, etc.
B2: Sub-Domain | C2: Source fields (What DDX field(s) is feeding this field?) | D2: Source tables (Key DDX end table source of truth) | E2: In GDM Analytics Version? | F2: In GDM Activation Version? | G2: In C360 Tables? | H2: In Glossary? | I2: Customer Relationship | J2: Definition
B3: Contact Info | C3: brand_code | D3: crm_base.mv_customer360_contacts | F3: Y | G3: Y | H3: Y | I3: one-to-one
B4: Contact Info | C4: division_code | D4: crm_base.mv_customer360_contacts | F4: Y | G4: Y | H4: Y | I4: one-to-one
B5: Contact Info | C5: brand_country | D5: crm_base.mv_customer360_contacts | G5: Y | H5: Y | I5: one-to-one
B6: Contact Info | C6: brand_mdm_id | D6: crm_base.mv_customer360_contacts | F6: Y | G6: Y | H6: Y | I6: one-to-one
B7: Contact Info | C7: contact_value | D7: crm_base.mv_customer360_contacts | G7: Y | H7: Y | I7: one-to-many
B8: Contact Info | C8: contact_type | D8: crm_base.mv_customer360_contacts | G8: Y | H8: Y | I8: one-to-many
B9: Contact Info | C9: contact_sub_type | D9: crm_base.mv_customer360_contacts | G9: Y | H9: Y | I9: one-to-many
B10: Contact Info | C10: last_modified_dt | D10: crm_base.dim_subscriber | F10: Y
B11: Contact Info | C11: email_perm_status | D11: crm_base.mv_customer360_contacts | F11: Y | G11: Y | H11: Y | I11: one-to-one
B12: Contact Info | C12: email_perm_status_modified_dt | D12: crm_base.mv_customer360_contacts | F12: Y | G12: Y | H12: Y | I12: one-to-one
B13: Contact Info | C13: Source of email opt-in collection | D13: TO CREATE PER NEW GDM SPECS | F13: Y
B14: Contact Info | C14: phone_perm_status | D14: crm_base.mv_customer360_contacts | F14: Y | G14: Y | H14: Y | I14: one-to-one
B15: Contact Info | C15: phone_perm_status_modified_dt | D15: crm_base.mv_customer360_contacts | F15: Y | G15: Y | H15: Y | I15: one-to-one
B16: Contact Info | C16: sms_perm_status | D16: crm_base.mv_customer360_contacts | F16: Y | G16: Y | H16: Y | I16: one-to-one
B17: Contact Info | C17: sms_perm_status_modified_dt | D17: crm_base.mv_customer360_contacts | F17: Y | G17: Y | H17: Y | I17: one-to-one
B18: Contact Info | C18: sms_perm_status_modified_src | D18: crm_base.dim_subscriber | F18: Y
B19: Contact Info | C19: sms_double_optin | D19: crm_base.mv_customer360_contacts | F19: Y | G19: Y | H19: Y | I19: one-to-one
B20: Contact Info | C20: sms_double_optin_modified_dt | D20: crm_base.mv_customer360_contacts | F20: Y | G20: Y | H20: Y | I20: one-to-one
B21: Contact Info | C21: sms_double_optin_modified_src | D21: crm_base.dim_subscriber | F21: Y
B22: Contact Info | C22: address_line1 | D22: crm_base.mv_customer360_contacts | G22: Y | H22: Y | I22: one-to-one
